<mujoco>
    <option gravity="0 0 -9.81" />
    <visual>
    <global offwidth="1920" offheight="1080"/>
    </visual>
  <worldbody>
    <light diffuse=".5 .5 .5" pos="0 0 5" dir="0 0 -1"/>
    <geom type="plane" size="10 10 0.1" rgba=".9 .9 .9 1"/>
    <body name="pillar" pos="0 0 2">
        <inertial mass="1" pos="0 0 0"/>
        <geom type="box" size=".1 .1 2" pos="0 0 0"/>

        <body name="pendulum" pos="0 -.4 2">
            <inertial mass="1" pos="0 0 0" diaginertia="1 1 0.1"/>
            <joint name="joint1" type="hinge" axis="0 -1 0" damping="0"/>
            <geom type="box" size=".1 .1 1" pos="0 0 -1"/>

            <body name="sphere" pos="0 0 -2">
                <inertial mass="3" pos="0 0 0" diaginertia="1 1 1"/>
                <geom type="sphere" size=".3" pos="0 0 0"/>
            </body>
        </body>
    </body>
  </worldbody>
    <keyframe>
        <key name="home" qpos="0.75"/>
    </keyframe>

    <actuator>
		  <motor ctrllimited="false" ctrlrange="-8 8" gear="1" joint="joint1" name="slide"/>
	  </actuator>
</mujoco>